2025-03-08 12:15:37,012 - ERROR - ---Argument: annio = 9998----------------------------------------------------------------
Traceback (most recent call last):
  File "C:\Users\Acer\Documents\Github\PI1_MLOps_mz\main.py", line 181, in UsersRecommend
    top3_most_recommended = [{"Puesto 1" : df_aux.iloc[0]['app_name']},
                                           ~~~~~~~~~~~^^^
  File "C:\Users\Acer\Documents\Github\PI1_MLOps_mz\my_venv\Lib\site-packages\pandas\core\indexing.py", line 1191, in __getitem__
    return self._getitem_axis(maybe_callable, axis=axis)
           ~~~~~~~~~~~~~~~~~~^^^^^^^^^^^^^^^^^^^^^^^^^^^
  File "C:\Users\Acer\Documents\Github\PI1_MLOps_mz\my_venv\Lib\site-packages\pandas\core\indexing.py", line 1752, in _getitem_axis
    self._validate_integer(key, axis)
    ~~~~~~~~~~~~~~~~~~~~~~^^^^^^^^^^^
  File "C:\Users\Acer\Documents\Github\PI1_MLOps_mz\my_venv\Lib\site-packages\pandas\core\indexing.py", line 1685, in _validate_integer
    raise IndexError("single positional indexer is out-of-bounds")
IndexError: single positional indexer is out-of-bounds
2025-03-08 12:29:45,239 - ERROR - ---Argument: genero = PRUEBA 1----------------------------------------------------------------
Traceback (most recent call last):
  File "C:\Users\Acer\Documents\Github\PI1_MLOps_mz\main.py", line 106, in PlayTimeGenre
    max_playtime_year = df_aux.loc[df_aux['playtime_forever'].idxmax()]['release_year']
                                   ~~~~~~~~~~~~~~~~~~~~~~~~~~~~~~~~~^^
  File "C:\Users\Acer\Documents\Github\PI1_MLOps_mz\my_venv\Lib\site-packages\pandas\core\series.py", line 2761, in idxmax
    i = self.argmax(axis, skipna, *args, **kwargs)
  File "C:\Users\Acer\Documents\Github\PI1_MLOps_mz\my_venv\Lib\site-packages\pandas\core\base.py", line 751, in argmax
    result = nanops.nanargmax(delegate, skipna=skipna)
  File "C:\Users\Acer\Documents\Github\PI1_MLOps_mz\my_venv\Lib\site-packages\pandas\core\nanops.py", line 1148, in nanargmax
    result = values.argmax(axis)
ValueError: attempt to get argmax of an empty sequence
2025-03-08 12:32:37,244 - ERROR - ---Argument: genero = PRUEBA 2----------------------------------------------------------------
Traceback (most recent call last):
  File "C:\Users\Acer\Documents\Github\PI1_MLOps_mz\main.py", line 141, in UserForGenre
    max_playtime_user = df_aux.groupby(['user_id'])['playtime_forever'].sum().reset_index().sort_values(by='playtime_forever', ascending=False).iloc[0]['user_id']
                        ~~~~~~~~~~~~~~~~~~~~~~~~~~~~~~~~~~~~~~~~~~~~~~~~~~~~~~~~~~~~~~~~~~~~~~~~~~~~~~~~~~~~~~~~~~~~~~~~~~~~~~~~~~~~~~~~~~~~~~~~~~~~^^^
  File "C:\Users\Acer\Documents\Github\PI1_MLOps_mz\my_venv\Lib\site-packages\pandas\core\indexing.py", line 1191, in __getitem__
    return self._getitem_axis(maybe_callable, axis=axis)
           ~~~~~~~~~~~~~~~~~~^^^^^^^^^^^^^^^^^^^^^^^^^^^
  File "C:\Users\Acer\Documents\Github\PI1_MLOps_mz\my_venv\Lib\site-packages\pandas\core\indexing.py", line 1752, in _getitem_axis
    self._validate_integer(key, axis)
    ~~~~~~~~~~~~~~~~~~~~~~^^^^^^^^^^^
  File "C:\Users\Acer\Documents\Github\PI1_MLOps_mz\my_venv\Lib\site-packages\pandas\core\indexing.py", line 1685, in _validate_integer
    raise IndexError("single positional indexer is out-of-bounds")
IndexError: single positional indexer is out-of-bounds
2025-03-08 12:36:02,612 - ERROR - ---Argument: annio = 99993----------------------------------------------------------------
Traceback (most recent call last):
  File "C:\Users\Acer\Documents\Github\PI1_MLOps_mz\main.py", line 181, in UsersRecommend
    top3_most_recommended = [{"Puesto 1" : df_aux.iloc[0]['app_name']},
                                           ~~~~~~~~~~~^^^
  File "C:\Users\Acer\Documents\Github\PI1_MLOps_mz\my_venv\Lib\site-packages\pandas\core\indexing.py", line 1191, in __getitem__
    return self._getitem_axis(maybe_callable, axis=axis)
           ~~~~~~~~~~~~~~~~~~^^^^^^^^^^^^^^^^^^^^^^^^^^^
  File "C:\Users\Acer\Documents\Github\PI1_MLOps_mz\my_venv\Lib\site-packages\pandas\core\indexing.py", line 1752, in _getitem_axis
    self._validate_integer(key, axis)
    ~~~~~~~~~~~~~~~~~~~~~~^^^^^^^^^^^
  File "C:\Users\Acer\Documents\Github\PI1_MLOps_mz\my_venv\Lib\site-packages\pandas\core\indexing.py", line 1685, in _validate_integer
    raise IndexError("single positional indexer is out-of-bounds")
IndexError: single positional indexer is out-of-bounds
2025-03-08 12:37:08,786 - ERROR - ---Argument: annio = 99994----------------------------------------------------------------
Traceback (most recent call last):
  File "C:\Users\Acer\Documents\Github\PI1_MLOps_mz\main.py", line 213, in UsersWorstDeveloper
    top3_least_recommended_dev = [{"Puesto 1" : df_aux.iloc[0]['developer']},
                                                ~~~~~~~~~~~^^^
  File "C:\Users\Acer\Documents\Github\PI1_MLOps_mz\my_venv\Lib\site-packages\pandas\core\indexing.py", line 1191, in __getitem__
    return self._getitem_axis(maybe_callable, axis=axis)
           ~~~~~~~~~~~~~~~~~~^^^^^^^^^^^^^^^^^^^^^^^^^^^
  File "C:\Users\Acer\Documents\Github\PI1_MLOps_mz\my_venv\Lib\site-packages\pandas\core\indexing.py", line 1752, in _getitem_axis
    self._validate_integer(key, axis)
    ~~~~~~~~~~~~~~~~~~~~~~^^^^^^^^^^^
  File "C:\Users\Acer\Documents\Github\PI1_MLOps_mz\my_venv\Lib\site-packages\pandas\core\indexing.py", line 1685, in _validate_integer
    raise IndexError("single positional indexer is out-of-bounds")
IndexError: single positional indexer is out-of-bounds
2025-03-08 12:38:05,543 - ERROR - ---Argument: empresa_desarrolladora = valve----------------------------------------------------------------
Traceback (most recent call last):
  File "C:\Users\Acer\Documents\Github\PI1_MLOps_mz\main.py", line 240, in sentiment_analysis
    raise ValueError(f"La empresa desarrolladora '{empresa_desarrolladora}' no se encuentra en el dataset")
ValueError: La empresa desarrolladora 'valve' no se encuentra en el dataset
2025-03-08 12:39:49,776 - ERROR - ---Argument: id = PRUEBA 6----------------------------------------------------------------
Traceback (most recent call last):
  File "C:\Users\Acer\Documents\Github\PI1_MLOps_mz\main.py", line 258, in recomendacion_juego
    idx = df2[df2['id'] == id].index[0]
          ~~~~~~~~~~~~~~~~~~~~~~~~~~^^^
  File "C:\Users\Acer\Documents\Github\PI1_MLOps_mz\my_venv\Lib\site-packages\pandas\core\indexes\base.py", line 5389, in __getitem__
    return getitem(key)
IndexError: index 0 is out of bounds for axis 0 with size 0
2025-03-08 12:47:41,117 - ERROR - Argument: genero = MIGUEL 1========================================================================
Traceback (most recent call last):
  File "C:\Users\Acer\Documents\Github\PI1_MLOps_mz\main.py", line 106, in PlayTimeGenre
    max_playtime_year = df_aux.loc[df_aux['playtime_forever'].idxmax()]['release_year']
                                   ~~~~~~~~~~~~~~~~~~~~~~~~~~~~~~~~~^^
  File "C:\Users\Acer\Documents\Github\PI1_MLOps_mz\my_venv\Lib\site-packages\pandas\core\series.py", line 2761, in idxmax
    i = self.argmax(axis, skipna, *args, **kwargs)
  File "C:\Users\Acer\Documents\Github\PI1_MLOps_mz\my_venv\Lib\site-packages\pandas\core\base.py", line 751, in argmax
    result = nanops.nanargmax(delegate, skipna=skipna)
  File "C:\Users\Acer\Documents\Github\PI1_MLOps_mz\my_venv\Lib\site-packages\pandas\core\nanops.py", line 1148, in nanargmax
    result = values.argmax(axis)
ValueError: attempt to get argmax of an empty sequence
2025-03-08 12:48:08,297 - ERROR - Argument: genero = MIGUEL 2========================================================================
Traceback (most recent call last):
  File "C:\Users\Acer\Documents\Github\PI1_MLOps_mz\main.py", line 141, in UserForGenre
    max_playtime_user = df_aux.groupby(['user_id'])['playtime_forever'].sum().reset_index().sort_values(by='playtime_forever', ascending=False).iloc[0]['user_id']
                        ~~~~~~~~~~~~~~~~~~~~~~~~~~~~~~~~~~~~~~~~~~~~~~~~~~~~~~~~~~~~~~~~~~~~~~~~~~~~~~~~~~~~~~~~~~~~~~~~~~~~~~~~~~~~~~~~~~~~~~~~~~~~^^^
  File "C:\Users\Acer\Documents\Github\PI1_MLOps_mz\my_venv\Lib\site-packages\pandas\core\indexing.py", line 1191, in __getitem__
    return self._getitem_axis(maybe_callable, axis=axis)
           ~~~~~~~~~~~~~~~~~~^^^^^^^^^^^^^^^^^^^^^^^^^^^
  File "C:\Users\Acer\Documents\Github\PI1_MLOps_mz\my_venv\Lib\site-packages\pandas\core\indexing.py", line 1752, in _getitem_axis
    self._validate_integer(key, axis)
    ~~~~~~~~~~~~~~~~~~~~~~^^^^^^^^^^^
  File "C:\Users\Acer\Documents\Github\PI1_MLOps_mz\my_venv\Lib\site-packages\pandas\core\indexing.py", line 1685, in _validate_integer
    raise IndexError("single positional indexer is out-of-bounds")
IndexError: single positional indexer is out-of-bounds
2025-03-08 12:48:34,644 - ERROR - Argument: annio = 3333========================================================================
Traceback (most recent call last):
  File "C:\Users\Acer\Documents\Github\PI1_MLOps_mz\main.py", line 181, in UsersRecommend
    top3_most_recommended = [{"Puesto 1" : df_aux.iloc[0]['app_name']},
                                           ~~~~~~~~~~~^^^
  File "C:\Users\Acer\Documents\Github\PI1_MLOps_mz\my_venv\Lib\site-packages\pandas\core\indexing.py", line 1191, in __getitem__
    return self._getitem_axis(maybe_callable, axis=axis)
           ~~~~~~~~~~~~~~~~~~^^^^^^^^^^^^^^^^^^^^^^^^^^^
  File "C:\Users\Acer\Documents\Github\PI1_MLOps_mz\my_venv\Lib\site-packages\pandas\core\indexing.py", line 1752, in _getitem_axis
    self._validate_integer(key, axis)
    ~~~~~~~~~~~~~~~~~~~~~~^^^^^^^^^^^
  File "C:\Users\Acer\Documents\Github\PI1_MLOps_mz\my_venv\Lib\site-packages\pandas\core\indexing.py", line 1685, in _validate_integer
    raise IndexError("single positional indexer is out-of-bounds")
IndexError: single positional indexer is out-of-bounds
2025-03-08 12:48:37,534 - ERROR - Argument: annio = 3333========================================================================
Traceback (most recent call last):
  File "C:\Users\Acer\Documents\Github\PI1_MLOps_mz\main.py", line 181, in UsersRecommend
    top3_most_recommended = [{"Puesto 1" : df_aux.iloc[0]['app_name']},
                                           ~~~~~~~~~~~^^^
  File "C:\Users\Acer\Documents\Github\PI1_MLOps_mz\my_venv\Lib\site-packages\pandas\core\indexing.py", line 1191, in __getitem__
    return self._getitem_axis(maybe_callable, axis=axis)
           ~~~~~~~~~~~~~~~~~~^^^^^^^^^^^^^^^^^^^^^^^^^^^
  File "C:\Users\Acer\Documents\Github\PI1_MLOps_mz\my_venv\Lib\site-packages\pandas\core\indexing.py", line 1752, in _getitem_axis
    self._validate_integer(key, axis)
    ~~~~~~~~~~~~~~~~~~~~~~^^^^^^^^^^^
  File "C:\Users\Acer\Documents\Github\PI1_MLOps_mz\my_venv\Lib\site-packages\pandas\core\indexing.py", line 1685, in _validate_integer
    raise IndexError("single positional indexer is out-of-bounds")
IndexError: single positional indexer is out-of-bounds
2025-03-08 12:48:57,468 - ERROR - Argument: annio = 4444========================================================================
Traceback (most recent call last):
  File "C:\Users\Acer\Documents\Github\PI1_MLOps_mz\main.py", line 213, in UsersWorstDeveloper
    top3_least_recommended_dev = [{"Puesto 1" : df_aux.iloc[0]['developer']},
                                                ~~~~~~~~~~~^^^
  File "C:\Users\Acer\Documents\Github\PI1_MLOps_mz\my_venv\Lib\site-packages\pandas\core\indexing.py", line 1191, in __getitem__
    return self._getitem_axis(maybe_callable, axis=axis)
           ~~~~~~~~~~~~~~~~~~^^^^^^^^^^^^^^^^^^^^^^^^^^^
  File "C:\Users\Acer\Documents\Github\PI1_MLOps_mz\my_venv\Lib\site-packages\pandas\core\indexing.py", line 1752, in _getitem_axis
    self._validate_integer(key, axis)
    ~~~~~~~~~~~~~~~~~~~~~~^^^^^^^^^^^
  File "C:\Users\Acer\Documents\Github\PI1_MLOps_mz\my_venv\Lib\site-packages\pandas\core\indexing.py", line 1685, in _validate_integer
    raise IndexError("single positional indexer is out-of-bounds")
IndexError: single positional indexer is out-of-bounds
2025-03-08 12:49:22,564 - ERROR - Argument: empresa_desarrolladora = MIGUEL ANGELLO========================================================================
Traceback (most recent call last):
  File "C:\Users\Acer\Documents\Github\PI1_MLOps_mz\main.py", line 240, in sentiment_analysis
    raise ValueError(f"La empresa desarrolladora '{empresa_desarrolladora}' no se encuentra en el dataset")
ValueError: La empresa desarrolladora 'MIGUEL ANGELLO' no se encuentra en el dataset
2025-03-08 12:49:54,255 - ERROR - Argument: id = PRUEBA 6========================================================================
Traceback (most recent call last):
  File "C:\Users\Acer\Documents\Github\PI1_MLOps_mz\main.py", line 258, in recomendacion_juego
    idx = df2[df2['id'] == id].index[0]
          ~~~~~~~~~~~~~~~~~~~~~~~~~~^^^
  File "C:\Users\Acer\Documents\Github\PI1_MLOps_mz\my_venv\Lib\site-packages\pandas\core\indexes\base.py", line 5389, in __getitem__
    return getitem(key)
IndexError: index 0 is out of bounds for axis 0 with size 0
