2025-03-08 11:16:41,989 - ERROR - ----------------------------Error------------------------------
Traceback (most recent call last):
  File "C:\Users\Acer\Documents\Github\PI1_MLOps_mz\main.py", line 106, in PlayTimeGenre
    max_playtime_year = df_aux.loc[df_aux['playtime_forever'].idxmax()]['release_year']
                                   ~~~~~~~~~~~~~~~~~~~~~~~~~~~~~~~~~^^
  File "C:\Users\Acer\Documents\Github\PI1_MLOps_mz\my_venv\Lib\site-packages\pandas\core\series.py", line 2761, in idxmax
    i = self.argmax(axis, skipna, *args, **kwargs)
  File "C:\Users\Acer\Documents\Github\PI1_MLOps_mz\my_venv\Lib\site-packages\pandas\core\base.py", line 751, in argmax
    result = nanops.nanargmax(delegate, skipna=skipna)
  File "C:\Users\Acer\Documents\Github\PI1_MLOps_mz\my_venv\Lib\site-packages\pandas\core\nanops.py", line 1148, in nanargmax
    result = values.argmax(axis)
ValueError: attempt to get argmax of an empty sequence
2025-03-08 11:18:42,988 - ERROR - ----------------------------Error------------------------------
Traceback (most recent call last):
  File "C:\Users\Acer\Documents\Github\PI1_MLOps_mz\main.py", line 141, in UserForGenre
    max_playtime_user = df_aux.groupby(['user_id'])['playtime_forever'].sum().reset_index().sort_values(by='playtime_forever', ascending=False).iloc[0]['user_id']
                        ~~~~~~~~~~~~~~~~~~~~~~~~~~~~~~~~~~~~~~~~~~~~~~~~~~~~~~~~~~~~~~~~~~~~~~~~~~~~~~~~~~~~~~~~~~~~~~~~~~~~~~~~~~~~~~~~~~~~~~~~~~~~^^^
  File "C:\Users\Acer\Documents\Github\PI1_MLOps_mz\my_venv\Lib\site-packages\pandas\core\indexing.py", line 1191, in __getitem__
    return self._getitem_axis(maybe_callable, axis=axis)
           ~~~~~~~~~~~~~~~~~~^^^^^^^^^^^^^^^^^^^^^^^^^^^
  File "C:\Users\Acer\Documents\Github\PI1_MLOps_mz\my_venv\Lib\site-packages\pandas\core\indexing.py", line 1752, in _getitem_axis
    self._validate_integer(key, axis)
    ~~~~~~~~~~~~~~~~~~~~~~^^^^^^^^^^^
  File "C:\Users\Acer\Documents\Github\PI1_MLOps_mz\my_venv\Lib\site-packages\pandas\core\indexing.py", line 1685, in _validate_integer
    raise IndexError("single positional indexer is out-of-bounds")
IndexError: single positional indexer is out-of-bounds
2025-03-08 11:20:18,512 - ERROR - ----------------------------Error------------------------------
Traceback (most recent call last):
  File "C:\Users\Acer\Documents\Github\PI1_MLOps_mz\main.py", line 181, in UsersRecommend
    top3_most_recommended = [{"Puesto 1" : df_aux.iloc[0]['app_name']},
                                           ~~~~~~~~~~~^^^
  File "C:\Users\Acer\Documents\Github\PI1_MLOps_mz\my_venv\Lib\site-packages\pandas\core\indexing.py", line 1191, in __getitem__
    return self._getitem_axis(maybe_callable, axis=axis)
           ~~~~~~~~~~~~~~~~~~^^^^^^^^^^^^^^^^^^^^^^^^^^^
  File "C:\Users\Acer\Documents\Github\PI1_MLOps_mz\my_venv\Lib\site-packages\pandas\core\indexing.py", line 1752, in _getitem_axis
    self._validate_integer(key, axis)
    ~~~~~~~~~~~~~~~~~~~~~~^^^^^^^^^^^
  File "C:\Users\Acer\Documents\Github\PI1_MLOps_mz\my_venv\Lib\site-packages\pandas\core\indexing.py", line 1685, in _validate_integer
    raise IndexError("single positional indexer is out-of-bounds")
IndexError: single positional indexer is out-of-bounds
2025-03-08 11:22:23,406 - ERROR - ----------------------------Error------------------------------
Traceback (most recent call last):
  File "C:\Users\Acer\Documents\Github\PI1_MLOps_mz\main.py", line 213, in UsersWorstDeveloper
    top3_least_recommended_dev = [{"Puesto 1" : df_aux.iloc[0]['developer']},
                                                ~~~~~~~~~~~^^^
  File "C:\Users\Acer\Documents\Github\PI1_MLOps_mz\my_venv\Lib\site-packages\pandas\core\indexing.py", line 1191, in __getitem__
    return self._getitem_axis(maybe_callable, axis=axis)
           ~~~~~~~~~~~~~~~~~~^^^^^^^^^^^^^^^^^^^^^^^^^^^
  File "C:\Users\Acer\Documents\Github\PI1_MLOps_mz\my_venv\Lib\site-packages\pandas\core\indexing.py", line 1752, in _getitem_axis
    self._validate_integer(key, axis)
    ~~~~~~~~~~~~~~~~~~~~~~^^^^^^^^^^^
  File "C:\Users\Acer\Documents\Github\PI1_MLOps_mz\my_venv\Lib\site-packages\pandas\core\indexing.py", line 1685, in _validate_integer
    raise IndexError("single positional indexer is out-of-bounds")
IndexError: single positional indexer is out-of-bounds
2025-03-08 11:23:17,913 - ERROR - ----------------------------Error------------------------------
Traceback (most recent call last):
  File "C:\Users\Acer\Documents\Github\PI1_MLOps_mz\main.py", line 240, in sentiment_analysis
    raise ValueError(f"La empresa desarrolladora '{empresa_desarrolladora}' no se encuentra en el dataset")
ValueError: La empresa desarrolladora 'JUNIOROYUELA' no se encuentra en el dataset
2025-03-08 11:26:17,835 - ERROR - ----------------------------Error------------------------------
Traceback (most recent call last):
  File "C:\Users\Acer\Documents\Github\PI1_MLOps_mz\main.py", line 258, in recomendacion_juego
    idx = df2[df2['id'] == id].index[0]
          ~~~~~~~~~~~~~~~~~~~~~~~~~~^^^
  File "C:\Users\Acer\Documents\Github\PI1_MLOps_mz\my_venv\Lib\site-packages\pandas\core\indexes\base.py", line 5389, in __getitem__
    return getitem(key)
IndexError: index 0 is out of bounds for axis 0 with size 0
2025-03-08 12:09:54,012 - ERROR - ---Argument: genero = JUNIOR----------------------------------------------------------------
Traceback (most recent call last):
  File "C:\Users\Acer\Documents\Github\PI1_MLOps_mz\main.py", line 106, in PlayTimeGenre
    max_playtime_year = df_aux.loc[df_aux['playtime_forever'].idxmax()]['release_year']
                                   ~~~~~~~~~~~~~~~~~~~~~~~~~~~~~~~~~^^
  File "C:\Users\Acer\Documents\Github\PI1_MLOps_mz\my_venv\Lib\site-packages\pandas\core\series.py", line 2761, in idxmax
    i = self.argmax(axis, skipna, *args, **kwargs)
  File "C:\Users\Acer\Documents\Github\PI1_MLOps_mz\my_venv\Lib\site-packages\pandas\core\base.py", line 751, in argmax
    result = nanops.nanargmax(delegate, skipna=skipna)
  File "C:\Users\Acer\Documents\Github\PI1_MLOps_mz\my_venv\Lib\site-packages\pandas\core\nanops.py", line 1148, in nanargmax
    result = values.argmax(axis)
ValueError: attempt to get argmax of an empty sequence
2025-03-08 12:11:28,056 - ERROR - ---Argument: genero = JUNIOR 2----------------------------------------------------------------
Traceback (most recent call last):
  File "C:\Users\Acer\Documents\Github\PI1_MLOps_mz\main.py", line 141, in UserForGenre
    max_playtime_user = df_aux.groupby(['user_id'])['playtime_forever'].sum().reset_index().sort_values(by='playtime_forever', ascending=False).iloc[0]['user_id']
                        ~~~~~~~~~~~~~~~~~~~~~~~~~~~~~~~~~~~~~~~~~~~~~~~~~~~~~~~~~~~~~~~~~~~~~~~~~~~~~~~~~~~~~~~~~~~~~~~~~~~~~~~~~~~~~~~~~~~~~~~~~~~~^^^
  File "C:\Users\Acer\Documents\Github\PI1_MLOps_mz\my_venv\Lib\site-packages\pandas\core\indexing.py", line 1191, in __getitem__
    return self._getitem_axis(maybe_callable, axis=axis)
           ~~~~~~~~~~~~~~~~~~^^^^^^^^^^^^^^^^^^^^^^^^^^^
  File "C:\Users\Acer\Documents\Github\PI1_MLOps_mz\my_venv\Lib\site-packages\pandas\core\indexing.py", line 1752, in _getitem_axis
    self._validate_integer(key, axis)
    ~~~~~~~~~~~~~~~~~~~~~~^^^^^^^^^^^
  File "C:\Users\Acer\Documents\Github\PI1_MLOps_mz\my_venv\Lib\site-packages\pandas\core\indexing.py", line 1685, in _validate_integer
    raise IndexError("single positional indexer is out-of-bounds")
IndexError: single positional indexer is out-of-bounds
2025-03-08 12:12:00,854 - ERROR - ---Argument: annio = 9999----------------------------------------------------------------
Traceback (most recent call last):
  File "C:\Users\Acer\Documents\Github\PI1_MLOps_mz\main.py", line 181, in UsersRecommend
    top3_most_recommended = [{"Puesto 1" : df_aux.iloc[0]['app_name']},
                                           ~~~~~~~~~~~^^^
  File "C:\Users\Acer\Documents\Github\PI1_MLOps_mz\my_venv\Lib\site-packages\pandas\core\indexing.py", line 1191, in __getitem__
    return self._getitem_axis(maybe_callable, axis=axis)
           ~~~~~~~~~~~~~~~~~~^^^^^^^^^^^^^^^^^^^^^^^^^^^
  File "C:\Users\Acer\Documents\Github\PI1_MLOps_mz\my_venv\Lib\site-packages\pandas\core\indexing.py", line 1752, in _getitem_axis
    self._validate_integer(key, axis)
    ~~~~~~~~~~~~~~~~~~~~~~^^^^^^^^^^^
  File "C:\Users\Acer\Documents\Github\PI1_MLOps_mz\my_venv\Lib\site-packages\pandas\core\indexing.py", line 1685, in _validate_integer
    raise IndexError("single positional indexer is out-of-bounds")
IndexError: single positional indexer is out-of-bounds
2025-03-08 12:14:15,436 - ERROR - ---Argument: annio = 9999----------------------------------------------------------------
Traceback (most recent call last):
  File "C:\Users\Acer\Documents\Github\PI1_MLOps_mz\main.py", line 181, in UsersRecommend
    top3_most_recommended = [{"Puesto 1" : df_aux.iloc[0]['app_name']},
                                           ~~~~~~~~~~~^^^
  File "C:\Users\Acer\Documents\Github\PI1_MLOps_mz\my_venv\Lib\site-packages\pandas\core\indexing.py", line 1191, in __getitem__
    return self._getitem_axis(maybe_callable, axis=axis)
           ~~~~~~~~~~~~~~~~~~^^^^^^^^^^^^^^^^^^^^^^^^^^^
  File "C:\Users\Acer\Documents\Github\PI1_MLOps_mz\my_venv\Lib\site-packages\pandas\core\indexing.py", line 1752, in _getitem_axis
    self._validate_integer(key, axis)
    ~~~~~~~~~~~~~~~~~~~~~~^^^^^^^^^^^
  File "C:\Users\Acer\Documents\Github\PI1_MLOps_mz\my_venv\Lib\site-packages\pandas\core\indexing.py", line 1685, in _validate_integer
    raise IndexError("single positional indexer is out-of-bounds")
IndexError: single positional indexer is out-of-bounds
